File: MatNavi Mechanical properties of low-alloy steels.csv
Alloy code, C, Si, Mn, P, S, Ni, Cr, Mo, Cu,V, Al, N,Ceq,Nb + Ta, Temperature (°C), 0.2% Proof Stress (MPa), Tensile Strength (MPa), Elongation (%), Reduction in Area (%)
MBB,0.12,0.36,0.52,0.009,0.003,0.089,0.97,0.61,0.04,0,0.003,0.0066,0,0,27,342,490,30,71
MBB,0.12,0.36,0.52,0.009,0.003,0.089,0.97,0.61,0.04,0,0.003,0.0066,0,0,200,337,465,23,69
MBB,0.12,0.36,0.52,0.009,0.003,0.089,0.97,0.61,0.04,0,0.003,0.0066,0,0,400,316,489,26,79
MBB,0.12,0.36,0.52,0.009,0.003,0.089,0.97,0.61,0.04,0,0.003,0.0066,0,0,500,274,431,28,85
MBB,0.12,0.36,0.52,0.009,0.003,0.089,0.97,0.61,0.04,0,0.003,0.0066,0,0,600,220,314,42,88
MBC,0.09,0.37,0.49,0.006,0.005,0.055,0.98,0.57,0.07,0,0.005,0.008,0,0,27,310,463,34,76
MBC,0.09,0.37,0.49,0.006,0.005,0.055,0.98,0.57,0.07,0,0.005,0.008,0,0,200,296,439,25,77
MBC,0.09,0.37,0.49,0.006,0.005,0.055,0.98,0.57,0.07,0,0.005,0.008,0,0,400,257,472,28,78
MBC,0.09,0.37,0.49,0.006,0.005,0.055,0.98,0.57,0.07,0,0.005,0.008,0,0,500,232,423,28,84
MBC,0.09,0.37,0.49,0.006,0.005,0.055,0.98,0.57,0.07,0,0.005,0.008,0,0,600,176,297,44,89
MBD,0.1,0.28,0.49,0.008,0.009,0.028,0.9,0.56,0.08,0,0.006,0.009,0,0,27,306,463,32,78
MBD,0.1,0.28,0.49,0.008,0.009,0.028,0.9,0.56,0.08,0,0.006,0.009,0,0,200,303,459,22,73
MBD,0.1,0.28,0.49,0.008,0.009,0.028,0.9,0.56,0.08,0,0.006,0.009,0,0,400,264,464,25,75
MBD,0.1,0.28,0.49,0.008,0.009,0.028,0.9,0.56,0.08,0,0.006,0.009,0,0,500,237,424,24,81
MBD,0.1,0.28,0.49,0.008,0.009,0.028,0.9,0.56,0.08,0,0.006,0.009,0,0,600,212,297,37,88
MBE,0.12,0.43,0.48,0.014,0.008,0.051,0.96,0.56,0.08,0,0.006,0.008,0,0,27,343,502,32,76
MBE,0.12,0.43,0.48,0.014,0.008,0.051,0.96,0.56,0.08,0,0.006,0.008,0,0,200,329,482,23,73
MBE,0.12,0.43,0.48,0.014,0.008,0.051,0.96,0.56,0.08,0,0.006,0.008,0,0,400,249,493,27,76
MBE,0.12,0.43,0.48,0.014,0.008,0.051,0.96,0.56,0.08,0,0.006,0.008,0,0,500,255,434,24,81
MBE,0.12,0.43,0.48,0.014,0.008,0.051,0.96,0.56,0.08,0,0.006,0.008,0,0,600,202,301,36,89
MBF,0.12,0.28,0.44,0.018,0.008,0.03,0.99,0.54,0.08,0,0.007,0.01,0,0,27,339,493,33,77
MBF,0.12,0.28,0.44,0.018,0.008,0.03,0.99,0.54,0.08,0,0.007,0.01,0,0,200,315,475,23,72
MBF,0.12,0.28,0.44,0.018,0.008,0.03,0.99,0.54,0.08,0,0.007,0.01,0,0,400,257,482,24,73
MBF,0.12,0.28,0.44,0.018,0.008,0.03,0.99,0.54,0.08,0,0.007,0.01,0,0,500,256,442,25,82
MBF,0.12,0.28,0.44,0.018,0.008,0.03,0.99,0.54,0.08,0,0.007,0.01,0,0,600,213,308,37,89
MBG,0.12,0.37,0.45,0.018,0.008,0.035,1,0.5,0.06,0,0.009,0.0088,0,0,27,251,456,32,73
MBG,0.12,0.37,0.45,0.018,0.008,0.035,1,0.5,0.06,0,0.009,0.0088,0,0,200,261,449,24,71
MBG,0.12,0.37,0.45,0.018,0.008,0.035,1,0.5,0.06,0,0.009,0.0088,0,0,400,192,482,27,76
MBG,0.12,0.37,0.45,0.018,0.008,0.035,1,0.5,0.06,0,0.009,0.0088,0,0,500,192,435,25,83
MBG,0.12,0.37,0.45,0.018,0.008,0.035,1,0.5,0.06,0,0.009,0.0088,0,0,600,170,304,38,89
MBH,0.12,0.36,0.45,0.018,0.007,0.028,1,0.53,0.05,0,0.007,0.008,0,0,27,239,453,35,72
MBH,0.12,0.36,0.45,0.018,0.007,0.028,1,0.53,0.05,0,0.007,0.008,0,0,200,244,449,23,70
MBH,0.12,0.36,0.45,0.018,0.007,0.028,1,0.53,0.05,0,0.007,0.008,0,0,400,174,474,27,74
MBH,0.12,0.36,0.45,0.018,0.007,0.028,1,0.53,0.05,0,0.007,0.008,0,0,500,181,434,26,82
MBH,0.12,0.36,0.45,0.018,0.007,0.028,1,0.53,0.05,0,0.007,0.008,0,0,600,170,296,38,89
MBJ,0.1,0.35,0.44,0.02,0.007,0.05,1.01,0.51,0.08,0,0.012,0.0082,0,0,27,241,431,36,76
MBJ,0.1,0.35,0.44,0.02,0.007,0.05,1.01,0.51,0.08,0,0.012,0.0082,0,0,200,243,431,24,72
MBJ,0.1,0.35,0.44,0.02,0.007,0.05,1.01,0.51,0.08,0,0.012,0.0082,0,0,400,168,454,27,77
MBJ,0.1,0.35,0.44,0.02,0.007,0.05,1.01,0.51,0.08,0,0.012,0.0082,0,0,500,160,417,28,81
MBJ,0.1,0.35,0.44,0.02,0.007,0.05,1.01,0.51,0.08,0,0.012,0.0082,0,0,600,161,293,38,88
MBL,0.09,0.32,0.48,0.02,0.017,0.023,1.05,0.52,0.04,0,0.009,0.0089,0,0,27,313,464,29,70
MBL,0.09,0.32,0.48,0.02,0.017,0.023,1.05,0.52,0.04,0,0.009,0.0089,0,0,200,324,459,22,67
MBL,0.09,0.32,0.48,0.02,0.017,0.023,1.05,0.52,0.04,0,0.009,0.0089,0,0,400,279,482,24,71
MBL,0.09,0.32,0.48,0.02,0.017,0.023,1.05,0.52,0.04,0,0.009,0.0089,0,0,500,262,449,24,76
MBL,0.09,0.32,0.48,0.02,0.017,0.023,1.05,0.52,0.04,0,0.009,0.0089,0,0,600,220,317,33,84
MBM,0.1,0.31,0.51,0.022,0.017,0.02,1.03,0.53,0.04,0,0.009,0.0076,0,0,27,291,462,30,71
MBM,0.1,0.31,0.51,0.022,0.017,0.02,1.03,0.53,0.04,0,0.009,0.0076,0,0,200,316,457,20,66
MBM,0.1,0.31,0.51,0.022,0.017,0.02,1.03,0.53,0.04,0,0.009,0.0076,0,0,400,270,482,24,71
MBM,0.1,0.31,0.51,0.022,0.017,0.02,1.03,0.53,0.04,0,0.009,0.0076,0,0,500,256,441,23,77
MBM,0.1,0.31,0.51,0.022,0.017,0.02,1.03,0.53,0.04,0,0.009,0.0076,0,0,600,218,299,42,87
MBN,0.1,0.3,0.49,0.02,0.018,0.023,1.04,0.5,0.04,0,0.009,0.0089,0,0,27,312,452,30,71
MBN,0.1,0.3,0.49,0.02,0.018,0.023,1.04,0.5,0.04,0,0.009,0.0089,0,0,200,311,454,22,64
MBN,0.1,0.3,0.49,0.02,0.018,0.023,1.04,0.5,0.04,0,0.009,0.0089,0,0,400,291,483,23,72
MBN,0.1,0.3,0.49,0.02,0.018,0.023,1.04,0.5,0.04,0,0.009,0.0089,0,0,500,260,448,24,77
MBN,0.1,0.3,0.49,0.02,0.018,0.023,1.04,0.5,0.04,0,0.009,0.0089,0,0,600,215,304,34,86
CAA,0.2,0.31,0.59,0.018,0.009,0,0.046,0.011,0.05,0,0.006,0.0056,0,0,27,280,480,31,64
CAA,0.2,0.31,0.59,0.018,0.009,0,0.046,0.011,0.05,0,0.006,0.0056,0,0,200,272,591,19,48
CAA,0.2,0.31,0.59,0.018,0.009,0,0.046,0.011,0.05,0,0.006,0.0056,0,0,350,185,509,34,66
CAA,0.2,0.31,0.59,0.018,0.009,0,0.046,0.011,0.05,0,0.006,0.0056,0,0,450,176,373,37,75
CAA,0.2,0.31,0.59,0.018,0.009,0,0.046,0.011,0.05,0,0.006,0.0056,0,0,550,131,234,61,90
CAB,0.2,0.28,0.6,0.018,0.008,0,0.045,0.01,0.05,0,0.005,0.0066,0,0,100,278,456,22,60
CAB,0.2,0.28,0.6,0.018,0.008,0,0.045,0.01,0.05,0,0.005,0.0066,0,0,300,187,540,30,58
CAB,0.2,0.28,0.6,0.018,0.008,0,0.045,0.01,0.05,0,0.005,0.0066,0,0,400,166,431,37,67
CAB,0.2,0.28,0.6,0.018,0.008,0,0.045,0.01,0.05,0,0.005,0.0066,0,0,500,152,302,40,83
CAC,0.2,0.29,0.55,0.021,0.009,0,0.054,0.012,0.05,0,0.004,0.0058,0,0,27,285,470,31,62
CAC,0.2,0.29,0.55,0.021,0.009,0,0.054,0.012,0.05,0,0.004,0.0058,0,0,200,267,564,18,48
CAC,0.2,0.29,0.55,0.021,0.009,0,0.054,0.012,0.05,0,0.004,0.0058,0,0,350,184,485,35,66
CAC,0.2,0.29,0.55,0.021,0.009,0,0.054,0.012,0.05,0,0.004,0.0058,0,0,450,179,372,36,78
CAC,0.2,0.29,0.55,0.021,0.009,0,0.054,0.012,0.05,0,0.004,0.0058,0,0,550,135,237,60,89
CAG,0.21,0.21,0.62,0.014,0.014,0,0.046,0.019,0.05,0,0.008,0.003,0,0,100,276,456,23,63
CAG,0.21,0.21,0.62,0.014,0.014,0,0.046,0.019,0.05,0,0.008,0.003,0,0,300,202,534,27,57
CAG,0.21,0.21,0.62,0.014,0.014,0,0.046,0.019,0.05,0,0.008,0.003,0,0,400,198,443,32,69
CAG,0.21,0.21,0.62,0.014,0.014,0,0.046,0.019,0.05,0,0.008,0.003,0,0,500,173,319,38,78
CAH,0.24,0.24,0.64,0.015,0.013,0,0.074,0.019,0.05,0,0.011,0.006,0,0,27,300,480,31,63
CAH,0.24,0.24,0.64,0.015,0.013,0,0.074,0.019,0.05,0,0.011,0.006,0,0,200,293,534,19,53
CAH,0.24,0.24,0.64,0.015,0.013,0,0.074,0.019,0.05,0,0.011,0.006,0,0,350,231,506,34,67
CAH,0.24,0.24,0.64,0.015,0.013,0,0.074,0.019,0.05,0,0.011,0.006,0,0,450,206,386,36,74
CAH,0.24,0.24,0.64,0.015,0.013,0,0.074,0.019,0.05,0,0.011,0.006,0,0,550,149,258,49,83
CAJ,0.2,0.2,0.47,0.007,0.009,0,0.056,0.01,0.07,0,0.005,0.011,0,0,100,297,510,19,51
CAJ,0.2,0.2,0.47,0.007,0.009,0,0.056,0.01,0.07,0,0.005,0.011,0,0,300,189,572,33,58
CAJ,0.2,0.2,0.47,0.007,0.009,0,0.056,0.01,0.07,0,0.005,0.011,0,0,400,193,426,40,68
CAJ,0.2,0.2,0.47,0.007,0.009,0,0.056,0.01,0.07,0,0.005,0.011,0,0,500,164,273,35,68
CAL,0.21,0.32,0.48,0.02,0.018,0,0.017,0.006,0.08,0,0.004,0.0044,0,0,27,275,460,33,64
CAL,0.21,0.32,0.48,0.02,0.018,0,0.017,0.006,0.08,0,0.004,0.0044,0,0,200,260,519,19,54
CAL,0.21,0.32,0.48,0.02,0.018,0,0.017,0.006,0.08,0,0.004,0.0044,0,0,350,188,469,32,67
CAL,0.21,0.32,0.48,0.02,0.018,0,0.017,0.006,0.08,0,0.004,0.0044,0,0,450,187,356,45,84
CAL,0.21,0.32,0.48,0.02,0.018,0,0.017,0.006,0.08,0,0.004,0.0044,0,0,550,137,227,50,88
CAM,0.2,0.31,0.5,0.022,0.017,0,0.017,0.006,0.09,0,0.004,0.0037,0,0,100,244,434,24,63
CAM,0.2,0.31,0.5,0.022,0.017,0,0.017,0.006,0.09,0,0.004,0.0037,0,0,300,202,509,30,60
CAM,0.2,0.31,0.5,0.022,0.017,0,0.017,0.006,0.09,0,0.004,0.0037,0,0,400,197,413,36,72
CAM,0.2,0.31,0.5,0.022,0.017,0,0.017,0.006,0.09,0,0.004,0.0037,0,0,500,160,276,42,84
CAN,0.23,0.32,0.53,0.023,0.016,0,0.022,0.005,0.07,0,0.005,0.0051,0,0,27,285,470,34,66
CAN,0.23,0.32,0.53,0.023,0.016,0,0.022,0.005,0.07,0,0.005,0.0051,0,0,200,251,502,20,56
CAN,0.23,0.32,0.53,0.023,0.016,0,0.022,0.005,0.07,0,0.005,0.0051,0,0,350,190,471,35,65
CAN,0.23,0.32,0.53,0.023,0.016,0,0.022,0.005,0.07,0,0.005,0.0051,0,0,450,202,343,40,77
CAN,0.23,0.32,0.53,0.023,0.016,0,0.022,0.005,0.07,0,0.005,0.0051,0,0,550,125,219,58,87
LAA,0.11,0.3,0.48,0.012,0.01,0,0,0.51,0,0,0.005,0.0078,0,0,100,260,442,26,67
LAA,0.11,0.3,0.48,0.012,0.01,0,0,0.51,0,0,0.005,0.0078,0,0,300,198,560,27,59
LAA,0.11,0.3,0.48,0.012,0.01,0,0,0.51,0,0,0.005,0.0078,0,0,450,181,447,28,78
LAA,0.11,0.3,0.48,0.012,0.01,0,0,0.51,0,0,0.005,0.0078,0,0,550,183,363,32,83
LAB,0.12,0.25,0.5,0.012,0.01,0,0,0.5,0,0,0.005,0.0068,0,0,27,270,460,34,69
LAB,0.12,0.25,0.5,0.012,0.01,0,0,0.5,0,0,0.005,0.0068,0,0,200,260,575,21,52
LAB,0.12,0.25,0.5,0.012,0.01,0,0,0.5,0,0,0.005,0.0068,0,0,400,204,484,31,73
LAB,0.12,0.25,0.5,0.012,0.01,0,0,0.5,0,0,0.005,0.0068,0,0,500,210,400,29,83
LAB,0.12,0.25,0.5,0.012,0.01,0,0,0.5,0,0,0.005,0.0068,0,0,600,163,272,48,89
LAC,0.13,0.31,0.48,0.006,0.007,0,0,0.49,0,0,0.005,0.006,0,0,100,248,439,24,66
LAC,0.13,0.31,0.48,0.006,0.007,0,0,0.49,0,0,0.005,0.006,0,0,300,177,571,28,58
LAC,0.13,0.31,0.48,0.006,0.007,0,0,0.49,0,0,0.005,0.006,0,0,450,189,451,28,78
LAC,0.13,0.31,0.48,0.006,0.007,0,0,0.49,0,0,0.005,0.006,0,0,550,193,353,32,84
LAD,0.15,0.22,0.43,0.011,0.022,0.01,0.02,0.5,0.03,0,0.004,0.004,0,0,27,280,430,36,71
LAD,0.15,0.22,0.43,0.011,0.022,0.01,0.02,0.5,0.03,0,0.004,0.004,0,0,200,273,533,20,61
LAD,0.15,0.22,0.43,0.011,0.022,0.01,0.02,0.5,0.03,0,0.004,0.004,0,0,400,181,428,31,68
LAD,0.15,0.22,0.43,0.011,0.022,0.01,0.02,0.5,0.03,0,0.004,0.004,0,0,500,180,350,30,78
LAD,0.15,0.22,0.43,0.011,0.022,0.01,0.02,0.5,0.03,0,0.004,0.004,0,0,600,140,250,44,86
LAE,0.14,0.22,0.46,0.012,0.012,0.01,0.03,0.5,0.03,0,0.006,0.006,0,0,100,274,423,21,67
LAE,0.14,0.22,0.46,0.012,0.012,0.01,0.03,0.5,0.03,0,0.006,0.006,0,0,300,218,530,27,37
LAE,0.14,0.22,0.46,0.012,0.012,0.01,0.03,0.5,0.03,0,0.006,0.006,0,0,450,200,393,28,72
LAE,0.14,0.22,0.46,0.012,0.012,0.01,0.03,0.5,0.03,0,0.006,0.006,0,0,550,213,311,30,82
LAF,0.15,0.25,0.58,0.008,0.01,0.05,0.11,0.52,0.04,0,0.007,0.011,0,0,27,290,450,36,74
LAF,0.15,0.25,0.58,0.008,0.01,0.05,0.11,0.52,0.04,0,0.007,0.011,0,0,200,260,463,22,68
LAF,0.15,0.25,0.58,0.008,0.01,0.05,0.11,0.52,0.04,0,0.007,0.011,0,0,400,182,438,32,73
LAF,0.15,0.25,0.58,0.008,0.01,0.05,0.11,0.52,0.04,0,0.007,0.011,0,0,500,167,372,29,80
LAF,0.15,0.25,0.58,0.008,0.01,0.05,0.11,0.52,0.04,0,0.007,0.011,0,0,600,146,253,44,87
LAG,0.2,0.28,0.59,0.012,0.01,0.02,0.02,0.54,0.07,0,0.003,0.0054,0,0,100,308,445,20,59
LAG,0.2,0.28,0.59,0.012,0.01,0.02,0.02,0.54,0.07,0,0.003,0.0054,0,0,300,278,557,24,28
LAG,0.2,0.28,0.59,0.012,0.01,0.02,0.02,0.54,0.07,0,0.003,0.0054,0,0,450,249,416,29,72
LAG,0.2,0.28,0.59,0.012,0.01,0.02,0.02,0.54,0.07,0,0.003,0.0054,0,0,550,237,321,30,84
LAH,0.17,0.3,0.63,0.012,0.012,0.04,0.09,0.52,0.1,0,0.003,0.007,0,0,27,320,480,30,64
LAH,0.17,0.3,0.63,0.012,0.012,0.04,0.09,0.52,0.1,0,0.003,0.007,0,0,200,310,592,17,45
LAH,0.17,0.3,0.63,0.012,0.012,0.04,0.09,0.52,0.1,0,0.003,0.007,0,0,400,238,487,27,61
LAH,0.17,0.3,0.63,0.012,0.012,0.04,0.09,0.52,0.1,0,0.003,0.007,0,0,500,248,385,34,77
LAH,0.17,0.3,0.63,0.012,0.012,0.04,0.09,0.52,0.1,0,0.003,0.007,0,0,600,177,268,39,83
LAJ,0.13,0.23,0.66,0.01,0.01,0.08,0.06,0.51,0.13,0,0.004,0.0057,0,0,100,408,512,20,64
LAJ,0.13,0.23,0.66,0.01,0.01,0.08,0.06,0.51,0.13,0,0.004,0.0057,0,0,300,263,541,27,54
LAJ,0.13,0.23,0.66,0.01,0.01,0.08,0.06,0.51,0.13,0,0.004,0.0057,0,0,450,261,407,31,71
LAJ,0.13,0.23,0.66,0.01,0.01,0.08,0.06,0.51,0.13,0,0.004,0.0057,0,0,550,215,317,32,81
LAL,0.14,0.39,0.63,0.008,0.005,0,0,0.58,0.03,0,0.004,0.006,0,0,27,420,530,23,65
LAL,0.14,0.39,0.63,0.008,0.005,0,0,0.58,0.03,0,0.004,0.006,0,0,200,412,616,17,52
LAL,0.14,0.39,0.63,0.008,0.005,0,0,0.58,0.03,0,0.004,0.006,0,0,400,367,532,26,64
LAL,0.14,0.39,0.63,0.008,0.005,0,0,0.58,0.03,0,0.004,0.006,0,0,500,306,420,27,79
LAL,0.14,0.39,0.63,0.008,0.005,0,0,0.58,0.03,0,0.004,0.006,0,0,600,243,304,32,83
LAM,0.14,0.4,0.67,0.007,0.004,0,0,0.6,0.03,0,0.004,0.007,0,0,100,380,506,19,61
LAM,0.14,0.4,0.67,0.007,0.004,0,0,0.6,0.03,0,0.004,0.007,0,0,300,378,614,23,51
LAM,0.14,0.4,0.67,0.007,0.004,0,0,0.6,0.03,0,0.004,0.007,0,0,450,328,477,27,71
LAM,0.14,0.4,0.67,0.007,0.004,0,0,0.6,0.03,0,0.004,0.007,0,0,550,268,369,35,86
LAN,0.14,0.39,0.64,0.006,0.005,0,0,0.58,0.03,0,0.005,0.008,0,0,27,380,520,25,64
LAN,0.14,0.39,0.64,0.006,0.005,0,0,0.58,0.03,0,0.005,0.008,0,0,200,367,606,18,48
LAN,0.14,0.39,0.64,0.006,0.005,0,0,0.58,0.03,0,0.005,0.008,0,0,400,323,517,26,64
LAN,0.14,0.39,0.64,0.006,0.005,0,0,0.58,0.03,0,0.005,0.008,0,0,500,276,417,28,80
LAN,0.14,0.39,0.64,0.006,0.005,0,0,0.58,0.03,0,0.005,0.008,0,0,600,217,291,46,84
CaC,0.28,0.3,0.7,0.022,0.011,0.14,0.07,0.02,0.22,0,0.004,0.0097,0,0,100,284,484,29,58
CaC,0.28,0.3,0.7,0.022,0.011,0.14,0.07,0.02,0.22,0,0.004,0.0097,0,0,300,223,483,26,48
CaC,0.28,0.3,0.7,0.022,0.011,0.14,0.07,0.02,0.22,0,0.004,0.0097,0,0,400,199,432,33,61
CaC,0.28,0.3,0.7,0.022,0.011,0.14,0.07,0.02,0.22,0,0.004,0.0097,0,0,500,165,314,39,69
CaD,0.2,0.22,0.68,0.024,0.009,0.15,0.11,0.03,0.23,0,0.01,0.0077,0,0,27,275,490,33,64
CaD,0.2,0.22,0.68,0.024,0.009,0.15,0.11,0.03,0.23,0,0.01,0.0077,0,0,200,243,439,28,62
CaD,0.2,0.22,0.68,0.024,0.009,0.15,0.11,0.03,0.23,0,0.01,0.0077,0,0,350,194,454,31,58
CaD,0.2,0.22,0.68,0.024,0.009,0.15,0.11,0.03,0.23,0,0.01,0.0077,0,0,450,183,368,43,74
CaD,0.2,0.22,0.68,0.024,0.009,0.15,0.11,0.03,0.23,0,0.01,0.0077,0,0,550,149,249,54,83
CaE,0.34,0.22,0.7,0.016,0.012,0.14,0.1,0.03,0.2,0,0.002,0.0107,0,0,100,266,454,31,61
CaE,0.34,0.22,0.7,0.016,0.012,0.14,0.1,0.03,0.2,0,0.002,0.0107,0,0,300,194,458,28,52
CaE,0.34,0.22,0.7,0.016,0.012,0.14,0.1,0.03,0.2,0,0.002,0.0107,0,0,400,194,422,31,62
CaE,0.34,0.22,0.7,0.016,0.012,0.14,0.1,0.03,0.2,0,0.002,0.0107,0,0,500,163,310,34,70
CaF,0.28,0.19,0.8,0.01,0.012,0,0.06,0.22,0.04,0,0.016,0.0073,0,0,27,275,490,30,56
CaF,0.28,0.19,0.8,0.01,0.012,0,0.06,0.22,0.04,0,0.016,0.0073,0,0,200,228,440,26,53
CaF,0.28,0.19,0.8,0.01,0.012,0,0.06,0.22,0.04,0,0.016,0.0073,0,0,350,179,457,30,60
CaF,0.28,0.19,0.8,0.01,0.012,0,0.06,0.22,0.04,0,0.016,0.0073,0,0,450,183,382,33,74
CaF,0.28,0.19,0.8,0.01,0.012,0,0.06,0.22,0.04,0,0.016,0.0073,0,0,550,149,256,37,81
CaG,0.29,0.2,0.93,0.014,0.015,0.03,0.03,0.36,0.06,0,0.018,0.0045,0,0,100,300,498,27,54
CaG,0.29,0.2,0.93,0.014,0.015,0.03,0.03,0.36,0.06,0,0.018,0.0045,0,0,300,235,522,22,47
CaG,0.29,0.2,0.93,0.014,0.015,0.03,0.03,0.36,0.06,0,0.018,0.0045,0,0,400,213,480,29,64
CaG,0.29,0.2,0.93,0.014,0.015,0.03,0.03,0.36,0.06,0,0.018,0.0045,0,0,500,213,380,28,73
CaH,0.29,0.22,1,0.016,0.011,0.05,0.07,0.34,0.05,0,0.011,0.0035,0,0,27,305,530,27,54
CaH,0.29,0.22,1,0.016,0.011,0.05,0.07,0.34,0.05,0,0.011,0.0035,0,0,200,259,478,23,50
CaH,0.29,0.22,1,0.016,0.011,0.05,0.07,0.34,0.05,0,0.011,0.0035,0,0,350,214,503,29,60
CaH,0.29,0.22,1,0.016,0.011,0.05,0.07,0.34,0.05,0,0.011,0.0035,0,0,450,202,424,33,73
CaH,0.29,0.22,1,0.016,0.011,0.05,0.07,0.34,0.05,0,0.011,0.0035,0,0,550,194,315,42,83
CaM,0.22,0.22,0.82,0.015,0.006,0.05,0.06,0.18,0.08,0,0.005,0.0082,0,0,100,289,443,28,63
CaM,0.22,0.22,0.82,0.015,0.006,0.05,0.06,0.18,0.08,0,0.005,0.0082,0,0,300,223,468,23,56
CaM,0.22,0.22,0.82,0.015,0.006,0.05,0.06,0.18,0.08,0,0.005,0.0082,0,0,400,194,408,33,71
CaM,0.22,0.22,0.82,0.015,0.006,0.05,0.06,0.18,0.08,0,0.005,0.0082,0,0,500,186,330,37,79
CaN,0.26,0.23,0.74,0.016,0.006,0.05,0.04,0.15,0.07,0,0.007,0.0108,0,0,27,270,480,30,58
CaN,0.26,0.23,0.74,0.016,0.006,0.05,0.04,0.15,0.07,0,0.007,0.0108,0,0,200,224,431,25,55
CaN,0.26,0.23,0.74,0.016,0.006,0.05,0.04,0.15,0.07,0,0.007,0.0108,0,0,350,205,526,26,53
CaN,0.26,0.23,0.74,0.016,0.006,0.05,0.04,0.15,0.07,0,0.007,0.0108,0,0,450,168,376,36,72
CaN,0.26,0.23,0.74,0.016,0.006,0.05,0.04,0.15,0.07,0,0.007,0.0108,0,0,550,153,268,51,82
VaA,0.28,0.2,0.72,0.015,0.012,0.32,1.02,1.12,0.2,0.27,0.002,0.0075,0,0,100,621,754,16,57
VaA,0.28,0.2,0.72,0.015,0.012,0.32,1.02,1.12,0.2,0.27,0.002,0.0075,0,0,300,580,722,15,52
VaA,0.28,0.2,0.72,0.015,0.012,0.32,1.02,1.12,0.2,0.27,0.002,0.0075,0,0,450,514,629,17,62
VaA,0.28,0.2,0.72,0.015,0.012,0.32,1.02,1.12,0.2,0.27,0.002,0.0075,0,0,550,469,504,19,80
VaA,0.28,0.2,0.72,0.015,0.012,0.32,1.02,1.12,0.2,0.27,0.002,0.0075,0,0,650,257,375,32,91
VaB,0.28,0.18,0.75,0.012,0.009,0.32,1,1.25,0.14,0.27,0.002,0.009,0,0,100,617,761,16,54
VaB,0.28,0.18,0.75,0.012,0.009,0.32,1,1.25,0.14,0.27,0.002,0.009,0,0,300,566,724,14,52
VaB,0.28,0.18,0.75,0.012,0.009,0.32,1,1.25,0.14,0.27,0.002,0.009,0,0,450,517,634,16,55
VaB,0.28,0.18,0.75,0.012,0.009,0.32,1,1.25,0.14,0.27,0.002,0.009,0,0,550,438,514,20,76
VaB,0.28,0.18,0.75,0.012,0.009,0.32,1,1.25,0.14,0.27,0.002,0.009,0,0,650,254,364,35,92
VaC,0.29,0.2,0.75,0.01,0.009,0.34,1,1.25,0.14,0.26,0.002,0.0075,0,0,100,662,786,16,58
VaC,0.29,0.2,0.75,0.01,0.009,0.34,1,1.25,0.14,0.26,0.002,0.0075,0,0,300,602,743,15,56
VaC,0.29,0.2,0.75,0.01,0.009,0.34,1,1.25,0.14,0.26,0.002,0.0075,0,0,450,544,644,16,62
VaC,0.29,0.2,0.75,0.01,0.009,0.34,1,1.25,0.14,0.26,0.002,0.0075,0,0,550,446,529,19,80
VaC,0.29,0.2,0.75,0.01,0.009,0.34,1,1.25,0.14,0.26,0.002,0.0075,0,0,650,256,376,37,93
VaD,0.3,0.28,0.72,0.014,0.006,0.35,0.93,1.22,0.16,0.21,0.002,0.0093,0,0,100,613,751,16,56
VaD,0.3,0.28,0.72,0.014,0.006,0.35,0.93,1.22,0.16,0.21,0.002,0.0093,0,0,300,569,731,13,49
VaD,0.3,0.28,0.72,0.014,0.006,0.35,0.93,1.22,0.16,0.21,0.002,0.0093,0,0,450,522,631,17,62
VaD,0.3,0.28,0.72,0.014,0.006,0.35,0.93,1.22,0.16,0.21,0.002,0.0093,0,0,550,432,510,19,77
VaD,0.3,0.28,0.72,0.014,0.006,0.35,0.93,1.22,0.16,0.21,0.002,0.0093,0,0,650,277,373,34,91
VaE,0.3,0.26,0.79,0.016,0.015,0.32,1.03,1.13,0.19,0.23,0.002,0.0085,0,0,100,585,738,16,57
VaE,0.3,0.26,0.79,0.016,0.015,0.32,1.03,1.13,0.19,0.23,0.002,0.0085,0,0,300,562,710,13,42
VaE,0.3,0.26,0.79,0.016,0.015,0.32,1.03,1.13,0.19,0.23,0.002,0.0085,0,0,450,501,619,16,61
VaE,0.3,0.26,0.79,0.016,0.015,0.32,1.03,1.13,0.19,0.23,0.002,0.0085,0,0,550,426,503,22,77
VaE,0.3,0.26,0.79,0.016,0.015,0.32,1.03,1.13,0.19,0.23,0.002,0.0085,0,0,650,250,367,27,90
VaG,0.29,0.26,0.76,0.009,0.007,0.45,1.12,1.18,0.07,0.23,0.003,0.0103,0,0,100,642,786,15,59
VaG,0.29,0.26,0.76,0.009,0.007,0.45,1.12,1.18,0.07,0.23,0.003,0.0103,0,0,300,596,746,14,51
VaG,0.29,0.26,0.76,0.009,0.007,0.45,1.12,1.18,0.07,0.23,0.003,0.0103,0,0,450,545,647,15,67
VaG,0.29,0.26,0.76,0.009,0.007,0.45,1.12,1.18,0.07,0.23,0.003,0.0103,0,0,550,463,537,21,83
VaG,0.29,0.26,0.76,0.009,0.007,0.45,1.12,1.18,0.07,0.23,0.003,0.0103,0,0,650,279,391,28,92
VaH,0.29,0.26,0.77,0.009,0.007,0.46,1.12,1.2,0.08,0.23,0.004,0.0095,0,0,100,622,775,16,61
VaH,0.29,0.26,0.77,0.009,0.007,0.46,1.12,1.2,0.08,0.23,0.004,0.0095,0,0,300,579,727,13,48
VaH,0.29,0.26,0.77,0.009,0.007,0.46,1.12,1.2,0.08,0.23,0.004,0.0095,0,0,450,522,632,16,54
VaH,0.29,0.26,0.77,0.009,0.007,0.46,1.12,1.2,0.08,0.23,0.004,0.0095,0,0,550,446,525,19,80
VaH,0.29,0.26,0.77,0.009,0.007,0.46,1.12,1.2,0.08,0.23,0.004,0.0095,0,0,650,284,391,25,89
Vaj,0.29,0.21,0.66,0.01,0.008,0.51,1.07,1.29,0.06,0.23,0.005,0.0097,0,0,100,601,748,17,62
Vaj,0.29,0.21,0.66,0.01,0.008,0.51,1.07,1.29,0.06,0.23,0.005,0.0097,0,0,300,560,716,14,55
Vaj,0.29,0.21,0.66,0.01,0.008,0.51,1.07,1.29,0.06,0.23,0.005,0.0097,0,0,450,508,612,18,67
Vaj,0.29,0.21,0.66,0.01,0.008,0.51,1.07,1.29,0.06,0.23,0.005,0.0097,0,0,550,430,506,20,83
Vaj,0.29,0.21,0.66,0.01,0.008,0.51,1.07,1.29,0.06,0.23,0.005,0.0097,0,0,650,267,370,32,91
VaR,0.3,0.27,0.7,0.012,0.012,0.44,1.1,1.35,0.11,0.27,0.003,0.0082,0,0,100,634,766,16,61
VaR,0.3,0.27,0.7,0.012,0.012,0.44,1.1,1.35,0.11,0.27,0.003,0.0082,0,0,300,585,737,14,53
VaR,0.3,0.27,0.7,0.012,0.012,0.44,1.1,1.35,0.11,0.27,0.003,0.0082,0,0,450,522,631,17,68
VaR,0.3,0.27,0.7,0.012,0.012,0.44,1.1,1.35,0.11,0.27,0.003,0.0082,0,0,550,437,522,20,84
VaR,0.3,0.27,0.7,0.012,0.012,0.44,1.1,1.35,0.11,0.27,0.003,0.0082,0,0,650,271,382,28,90
LaA,0.18,0.26,1.33,0.015,0.008,0.55,0.11,0.49,0.11,0,0.028,0.006,0,0,100,393,525,23,69
LaA,0.18,0.26,1.33,0.015,0.008,0.55,0.11,0.49,0.11,0,0.028,0.006,0,0,300,395,588,21,62
LaA,0.18,0.26,1.33,0.015,0.008,0.55,0.11,0.49,0.11,0,0.028,0.006,0,0,400,367,534,25,71
LaA,0.18,0.26,1.33,0.015,0.008,0.55,0.11,0.49,0.11,0,0.028,0.006,0,0,500,322,409,23,78
LaA,0.18,0.26,1.33,0.015,0.008,0.55,0.11,0.49,0.11,0,0.028,0.006,0,0,600,240,313,31,84
LaB,0.17,0.23,1.34,0.014,0.009,0.57,0.16,0.49,0.11,0,0.038,0.007,0,0,100,427,548,23,71
LaB,0.17,0.23,1.34,0.014,0.009,0.57,0.16,0.49,0.11,0,0.038,0.007,0,0,300,435,608,20,61
LaB,0.17,0.23,1.34,0.014,0.009,0.57,0.16,0.49,0.11,0,0.038,0.007,0,0,400,366,531,26,68
LaB,0.17,0.23,1.34,0.014,0.009,0.57,0.16,0.49,0.11,0,0.038,0.007,0,0,500,337,427,22,79
LaB,0.17,0.23,1.34,0.014,0.009,0.57,0.16,0.49,0.11,0,0.038,0.007,0,0,600,248,308,37,85
LaD,0.17,0.33,1.37,0.016,0.014,0.6,0.08,0.53,0.24,0,0.008,0.0071,0,0,100,421,558,21,68
LaD,0.17,0.33,1.37,0.016,0.014,0.6,0.08,0.53,0.24,0,0.008,0.0071,0,0,300,400,565,18,60
LaD,0.17,0.33,1.37,0.016,0.014,0.6,0.08,0.53,0.24,0,0.008,0.0071,0,0,400,378,532,19,45
LaD,0.17,0.33,1.37,0.016,0.014,0.6,0.08,0.53,0.24,0,0.008,0.0071,0,0,500,341,473,23,75
LaD,0.17,0.33,1.37,0.016,0.014,0.6,0.08,0.53,0.24,0,0.008,0.0071,0,0,600,250,310,30,88
LaE,0.17,0.35,1.44,0.015,0.01,0.58,0.08,0.5,0.23,0,0.006,0.0079,0,0,27,420,580,27,71
LaE,0.17,0.35,1.44,0.015,0.01,0.58,0.08,0.5,0.23,0,0.006,0.0079,0,0,200,381,525,22,69
LaE,0.17,0.35,1.44,0.015,0.01,0.58,0.08,0.5,0.23,0,0.006,0.0079,0,0,350,357,549,24,62
LaE,0.17,0.35,1.44,0.015,0.01,0.58,0.08,0.5,0.23,0,0.006,0.0079,0,0,450,336,462,22,66
LaE,0.17,0.35,1.44,0.015,0.01,0.58,0.08,0.5,0.23,0,0.006,0.0079,0,0,550,286,355,31,84
LaF,0.19,0.33,1.41,0.014,0.006,0.58,0.1,0.53,0.25,0,0.008,0.0077,0,0,27,435,590,26,72
LaF,0.19,0.33,1.41,0.014,0.006,0.58,0.1,0.53,0.25,0,0.008,0.0077,0,0,200,395,540,23,69
LaF,0.19,0.33,1.41,0.014,0.006,0.58,0.1,0.53,0.25,0,0.008,0.0077,0,0,350,370,558,23,60
LaF,0.19,0.33,1.41,0.014,0.006,0.58,0.1,0.53,0.25,0,0.008,0.0077,0,0,450,335,470,22,64
LaF,0.19,0.33,1.41,0.014,0.006,0.58,0.1,0.53,0.25,0,0.008,0.0077,0,0,550,288,356,29,83
MFA,0.12,0.25,0.48,0.008,0.012,0.04,0.64,0.51,0.04,0,0.006,0.013,0,0,27,270,480,32,75
MFA,0.12,0.25,0.48,0.008,0.012,0.04,0.64,0.51,0.04,0,0.006,0.013,0,0,200,261,542,20,59
MFA,0.12,0.25,0.48,0.008,0.012,0.04,0.64,0.51,0.04,0,0.006,0.013,0,0,400,237,564,26,66
MFA,0.12,0.25,0.48,0.008,0.012,0.04,0.64,0.51,0.04,0,0.006,0.013,0,0,500,237,487,25,70
MFA,0.12,0.25,0.48,0.008,0.012,0.04,0.64,0.51,0.04,0,0.006,0.013,0,0,600,193,332,42,84
MFB,0.16,0.24,0.49,0.012,0.007,0.035,0.61,0.51,0.04,0,0.006,0.0086,0,0,100,260,408,29,67
MFB,0.16,0.24,0.49,0.012,0.007,0.035,0.61,0.51,0.04,0,0.006,0.0086,0,0,300,192,493,21,57
MFB,0.16,0.24,0.49,0.012,0.007,0.035,0.61,0.51,0.04,0,0.006,0.0086,0,0,450,180,434,28,79
MFB,0.16,0.24,0.49,0.012,0.007,0.035,0.61,0.51,0.04,0,0.006,0.0086,0,0,550,176,349,37,87
MFD,0.12,0.25,0.43,0.006,0.011,0.03,0.59,0.51,0.03,0,0.006,0.015,0,0,27,325,460,36,77
MFD,0.12,0.25,0.43,0.006,0.011,0.03,0.59,0.51,0.03,0,0.006,0.015,0,0,200,284,435,25,76
MFD,0.12,0.25,0.43,0.006,0.011,0.03,0.59,0.51,0.03,0,0.006,0.015,0,0,400,213,455,29,78
MFD,0.12,0.25,0.43,0.006,0.011,0.03,0.59,0.51,0.03,0,0.006,0.015,0,0,500,208,402,26,83
MFD,0.12,0.25,0.43,0.006,0.011,0.03,0.59,0.51,0.03,0,0.006,0.015,0,0,600,168,283,46,90
MFE,0.12,0.25,0.44,0.013,0.012,0.05,0.71,0.52,0.06,0,0.004,0.0058,0,0,100,276,438,26,66
MFE,0.12,0.25,0.44,0.013,0.012,0.05,0.71,0.52,0.06,0,0.004,0.0058,0,0,300,260,557,20,50
MFE,0.12,0.25,0.44,0.013,0.012,0.05,0.71,0.52,0.06,0,0.004,0.0058,0,0,450,228,507,24,63
MFE,0.12,0.25,0.44,0.013,0.012,0.05,0.71,0.52,0.06,0,0.004,0.0058,0,0,550,220,418,27,76
MFF,0.12,0.24,0.47,0.008,0.011,0.04,0.71,0.49,0.06,0,0.006,0.013,0,0,27,275,480,33,75
MFF,0.12,0.24,0.47,0.008,0.011,0.04,0.71,0.49,0.06,0,0.006,0.013,0,0,200,270,522,21,64
MFF,0.12,0.24,0.47,0.008,0.011,0.04,0.71,0.49,0.06,0,0.006,0.013,0,0,400,246,556,26,64
MFF,0.12,0.24,0.47,0.008,0.011,0.04,0.71,0.49,0.06,0,0.006,0.013,0,0,500,232,474,25,73
MFF,0.12,0.24,0.47,0.008,0.011,0.04,0.71,0.49,0.06,0,0.006,0.013,0,0,600,198,313,47,88
MFG,0.15,0.26,0.45,0.012,0.006,0.033,0.58,0.49,0.04,0,0.006,0.0084,0,0,100,261,418,32,65
MFG,0.15,0.26,0.45,0.012,0.006,0.033,0.58,0.49,0.04,0,0.006,0.0084,0,0,300,192,492,21,57
MFG,0.15,0.26,0.45,0.012,0.006,0.033,0.58,0.49,0.04,0,0.006,0.0084,0,0,450,178,424,30,81
MFG,0.15,0.26,0.45,0.012,0.006,0.033,0.58,0.49,0.04,0,0.006,0.0084,0,0,550,178,337,37,88
MFH,0.14,0.22,0.45,0.013,0.013,0.06,0.68,0.52,0.06,0,0.004,0.0062,0,0,27,250,470,33,65
MFH,0.14,0.22,0.45,0.013,0.013,0.06,0.68,0.52,0.06,0,0.004,0.0062,0,0,200,251,522,19,52
MFH,0.14,0.22,0.45,0.013,0.013,0.06,0.68,0.52,0.06,0,0.004,0.0062,0,0,400,254,524,25,60
MFH,0.14,0.22,0.45,0.013,0.013,0.06,0.68,0.52,0.06,0,0.004,0.0062,0,0,500,207,462,27,71
MFH,0.14,0.22,0.45,0.013,0.013,0.06,0.68,0.52,0.06,0,0.004,0.0062,0,0,600,202,328,41,82
MFL,0.15,0.21,0.42,0.015,0.011,0.06,0.66,0.52,0.07,0,0.004,0.0056,0,0,100,221,411,26,63
MFL,0.15,0.21,0.42,0.015,0.011,0.06,0.66,0.52,0.07,0,0.004,0.0056,0,0,300,223,544,20,50
MFL,0.15,0.21,0.42,0.015,0.011,0.06,0.66,0.52,0.07,0,0.004,0.0056,0,0,450,202,486,26,64
MFL,0.15,0.21,0.42,0.015,0.011,0.06,0.66,0.52,0.07,0,0.004,0.0056,0,0,550,203,395,31,78
MFM,0.15,0.25,0.45,0.013,0.008,0.032,0.6,0.48,0.04,0,0.006,0.0082,0,0,27,265,450,33,66
MFM,0.15,0.25,0.45,0.013,0.008,0.032,0.6,0.48,0.04,0,0.006,0.0082,0,0,200,254,448,22,59
MFM,0.15,0.25,0.45,0.013,0.008,0.032,0.6,0.48,0.04,0,0.006,0.0082,0,0,400,180,452,31,75
MFM,0.15,0.25,0.45,0.013,0.008,0.032,0.6,0.48,0.04,0,0.006,0.0082,0,0,500,172,385,33,85
MFM,0.15,0.25,0.45,0.013,0.008,0.032,0.6,0.48,0.04,0,0.006,0.0082,0,0,600,160,269,46,89
VbA,0.17,0.39,0.6,0.022,0.02,0.11,1.31,1.02,0.11,0.28,0.004,0.0078,0,0,100,532,666,17,50
VbA,0.17,0.39,0.6,0.022,0.02,0.11,1.31,1.02,0.11,0.28,0.004,0.0078,0,0,300,499,644,15,46
VbA,0.17,0.39,0.6,0.022,0.02,0.11,1.31,1.02,0.11,0.28,0.004,0.0078,0,0,450,437,567,18,57
VbA,0.17,0.39,0.6,0.022,0.02,0.11,1.31,1.02,0.11,0.28,0.004,0.0078,0,0,550,428,492,17,54
VbA,0.17,0.39,0.6,0.022,0.02,0.11,1.31,1.02,0.11,0.28,0.004,0.0078,0,0,650,259,330,29,88
VbB,0.16,0.47,0.62,0.01,0.01,0.19,1.01,0.92,0.15,0.24,0.003,0.0111,0,0,100,521,661,17,62
VbB,0.16,0.47,0.62,0.01,0.01,0.19,1.01,0.92,0.15,0.24,0.003,0.0111,0,0,300,491,626,13,52
VbB,0.16,0.47,0.62,0.01,0.01,0.19,1.01,0.92,0.15,0.24,0.003,0.0111,0,0,450,449,566,16,54
VbB,0.16,0.47,0.62,0.01,0.01,0.19,1.01,0.92,0.15,0.24,0.003,0.0111,0,0,550,382,449,18,72
VbB,0.16,0.47,0.62,0.01,0.01,0.19,1.01,0.92,0.15,0.24,0.003,0.0111,0,0,650,261,339,23,86
VbD,0.14,0.34,0.73,0.01,0.009,0.13,1.06,0.96,0.08,0.23,0.003,0.0102,0,0,100,570,678,13,37
VbD,0.14,0.34,0.73,0.01,0.009,0.13,1.06,0.96,0.08,0.23,0.003,0.0102,0,0,300,506,626,13,34
VbD,0.14,0.34,0.73,0.01,0.009,0.13,1.06,0.96,0.08,0.23,0.003,0.0102,0,0,450,462,554,16,55
VbD,0.14,0.34,0.73,0.01,0.009,0.13,1.06,0.96,0.08,0.23,0.003,0.0102,0,0,550,403,462,20,75
VbD,0.14,0.34,0.73,0.01,0.009,0.13,1.06,0.96,0.08,0.23,0.003,0.0102,0,0,650,283,352,22,82
VbF,0.18,0.37,0.66,0.018,0.017,0.1,1.07,1.03,0.12,0.3,0.02,0.0081,0,0,100,584,716,13,47
VbF,0.18,0.37,0.66,0.018,0.017,0.1,1.07,1.03,0.12,0.3,0.02,0.0081,0,0,300,519,6661,11,28
VbF,0.18,0.37,0.66,0.018,0.017,0.1,1.07,1.03,0.12,0.3,0.02,0.0081,0,0,450,471,592,15,44
VbF,0.18,0.37,0.66,0.018,0.017,0.1,1.07,1.03,0.12,0.3,0.02,0.0081,0,0,550,473,535,15,68
VbF,0.18,0.37,0.66,0.018,0.017,0.1,1.07,1.03,0.12,0.3,0.02,0.0081,0,0,650,278,343,23,82
VbG,0.16,0.47,0.62,0.01,0.01,0.19,1,0.92,0.15,0.24,0.002,0.0104,0,0,100,508,644,17,62
VbG,0.16,0.47,0.62,0.01,0.01,0.19,1,0.92,0.15,0.24,0.002,0.0104,0,0,300,464,593,14,54
VbG,0.16,0.47,0.62,0.01,0.01,0.19,1,0.92,0.15,0.24,0.002,0.0104,0,0,450,447,551,12,40
VbG,0.16,0.47,0.62,0.01,0.01,0.19,1,0.92,0.15,0.24,0.002,0.0104,0,0,550,384,450,15,62
VbG,0.16,0.47,0.62,0.01,0.01,0.19,1,0.92,0.15,0.24,0.002,0.0104,0,0,650,269,342,29,86
VbH,0.18,0.37,0.61,0.019,0.018,0.11,1.09,1.12,0.07,0.28,0.016,0.0064,0,0,100,520,653,17,57
VbH,0.18,0.37,0.61,0.019,0.018,0.11,1.09,1.12,0.07,0.28,0.016,0.0064,0,0,300,199,660,12,45
VbH,0.18,0.37,0.61,0.019,0.018,0.11,1.09,1.12,0.07,0.28,0.016,0.0064,0,0,450,534,632,15,51
VbH,0.18,0.37,0.61,0.019,0.018,0.11,1.09,1.12,0.07,0.28,0.016,0.0064,0,0,550,445,517,16,68
VbH,0.18,0.37,0.61,0.019,0.018,0.11,1.09,1.12,0.07,0.28,0.016,0.0064,0,0,650,318,393,21,78
VbJ,0.16,0.52,0.79,0.01,0.008,0.13,1.16,0.97,0.11,0.23,0.003,0.0106,0,0,100,540,665,15,58
VbJ,0.16,0.52,0.79,0.01,0.008,0.13,1.16,0.97,0.11,0.23,0.003,0.0106,0,0,300,513,660,15,52
VbJ,0.16,0.52,0.79,0.01,0.008,0.13,1.16,0.97,0.11,0.23,0.003,0.0106,0,0,450,463,580,19,67
VbJ,0.16,0.52,0.79,0.01,0.008,0.13,1.16,0.97,0.11,0.23,0.003,0.0106,0,0,550,395,465,21,80
VbJ,0.16,0.52,0.79,0.01,0.008,0.13,1.16,0.97,0.11,0.23,0.003,0.0106,0,0,650,262,341,31,91
VbM,0.18,0.39,0.63,0.012,0.012,0.23,1.22,0.89,0.17,0.23,0.002,0.0103,0,0,100,499,635,18,64
VbM,0.18,0.39,0.63,0.012,0.012,0.23,1.22,0.89,0.17,0.23,0.002,0.0103,0,0,300,459,601,15,56
VbM,0.18,0.39,0.63,0.012,0.012,0.23,1.22,0.89,0.17,0.23,0.002,0.0103,0,0,450,434,542,17,60
VbM,0.18,0.39,0.63,0.012,0.012,0.23,1.22,0.89,0.17,0.23,0.002,0.0103,0,0,550,380,446,18,74
VbM,0.18,0.39,0.63,0.012,0.012,0.23,1.22,0.89,0.17,0.23,0.002,0.0103,0,0,650,262,333,20,83
VbN,0.15,0.52,0.78,0.01,0.009,0.12,1.17,0.98,0.08,0.23,0.003,0.0106,0,0,100,534,654,18,68
VbN,0.15,0.52,0.78,0.01,0.009,0.12,1.17,0.98,0.08,0.23,0.003,0.0106,0,0,300,496,607,16,66
VbN,0.15,0.52,0.78,0.01,0.009,0.12,1.17,0.98,0.08,0.23,0.003,0.0106,0,0,450,450,540,18,70
VbN,0.15,0.52,0.78,0.01,0.009,0.12,1.17,0.98,0.08,0.23,0.003,0.0106,0,0,550,408,162,18,80
VbN,0.15,0.52,0.78,0.01,0.009,0.12,1.17,0.98,0.08,0.23,0.003,0.0106,0,0,650,252,333,23,88
CbA,0.15,0.3,1.14,0.009,0.021,0.31,0.2,0.08,0.14,0,0.028,0.0082,0.42,0,100,434,545,22,73
CbA,0.15,0.3,1.14,0.009,0.021,0.31,0.2,0.08,0.14,0,0.028,0.0082,0.42,0,300,421,596,24,64
CbA,0.15,0.3,1.14,0.009,0.021,0.31,0.2,0.08,0.14,0,0.028,0.0082,0.42,0,400,410,513,29,74
CbA,0.15,0.3,1.14,0.009,0.021,0.31,0.2,0.08,0.14,0,0.028,0.0082,0.42,0,500,349,426,26,81
CbA,0.15,0.3,1.14,0.009,0.021,0.31,0.2,0.08,0.14,0,0.028,0.0082,0.42,0,600,194,276,42,71
CbB,0.15,0.28,1.32,0.019,0.005,0.077,0.053,0.008,0.08,0.07,0.017,0.0066,0.401,0,100,513,645,18,60
CbB,0.15,0.28,1.32,0.019,0.005,0.077,0.053,0.008,0.08,0.07,0.017,0.0066,0.401,0,300,452,634,19,58
CbB,0.15,0.28,1.32,0.019,0.005,0.077,0.053,0.008,0.08,0.07,0.017,0.0066,0.401,0,400,415,569,23,69
CbB,0.15,0.28,1.32,0.019,0.005,0.077,0.053,0.008,0.08,0.07,0.017,0.0066,0.401,0,500,303,410,24,79
CbB,0.15,0.28,1.32,0.019,0.005,0.077,0.053,0.008,0.08,0.07,0.017,0.0066,0.401,0,600,189,288,28,80
CbC,0.16,0.28,1.14,0.017,0.016,0.33,0.24,0.08,0.13,0,0.015,0.0067,0.437,0,100,591,682,17,66
CbC,0.16,0.28,1.14,0.017,0.016,0.33,0.24,0.08,0.13,0,0.015,0.0067,0.437,0,300,566,701,21,61
CbC,0.16,0.28,1.14,0.017,0.016,0.33,0.24,0.08,0.13,0,0.015,0.0067,0.437,0,400,530,600,23,72
CbC,0.16,0.28,1.14,0.017,0.016,0.33,0.24,0.08,0.13,0,0.015,0.0067,0.437,0,500,403,476,22,75
CbC,0.16,0.28,1.14,0.017,0.016,0.33,0.24,0.08,0.13,0,0.015,0.0067,0.437,0,600,186,316,31,45
CbD,0.16,0.48,1.21,0.017,0.009,0.02,0.02,0.1,0.02,0.05,0.04,0.0028,0.414,0,100,512,637,20,71
CbD,0.16,0.48,1.21,0.017,0.009,0.02,0.02,0.1,0.02,0.05,0.04,0.0028,0.414,0,300,486,649,21,73
CbD,0.16,0.48,1.21,0.017,0.009,0.02,0.02,0.1,0.02,0.05,0.04,0.0028,0.414,0,400,431,567,24,82
CbD,0.16,0.48,1.21,0.017,0.009,0.02,0.02,0.1,0.02,0.05,0.04,0.0028,0.414,0,500,380,466,22,87
CbD,0.16,0.48,1.21,0.017,0.009,0.02,0.02,0.1,0.02,0.05,0.04,0.0028,0.414,0,600,252,338,27,86
CbE,0.13,0.33,1.23,0.014,0.015,0.44,0.04,0.076,0.04,0.04,0.032,0.0074,0.389,0,100,500,592,21,70
CbE,0.13,0.33,1.23,0.014,0.015,0.44,0.04,0.076,0.04,0.04,0.032,0.0074,0.389,0,300,459,624,24,68
CbE,0.13,0.33,1.23,0.014,0.015,0.44,0.04,0.076,0.04,0.04,0.032,0.0074,0.389,0,400,399,530,25,75
CbE,0.13,0.33,1.23,0.014,0.015,0.44,0.04,0.076,0.04,0.04,0.032,0.0074,0.389,0,500,368,430,29,85
CbE,0.13,0.33,1.23,0.014,0.015,0.44,0.04,0.076,0.04,0.04,0.032,0.0074,0.389,0,600,218,300,37,82
CbF,0.14,0.3,1.09,0.008,0.015,0.39,0.12,0.09,0.17,0,0.032,0.0098,0.39,0,100,424,534,23,72
CbF,0.14,0.3,1.09,0.008,0.015,0.39,0.12,0.09,0.17,0,0.032,0.0098,0.39,0,300,396,571,24,62
CbF,0.14,0.3,1.09,0.008,0.015,0.39,0.12,0.09,0.17,0,0.032,0.0098,0.39,0,400,351,490,27,72
CbF,0.14,0.3,1.09,0.008,0.015,0.39,0.12,0.09,0.17,0,0.032,0.0098,0.39,0,500,300,380,25,76
CbF,0.14,0.3,1.09,0.008,0.015,0.39,0.12,0.09,0.17,0,0.032,0.0098,0.39,0,600,189,269,39,74
CbG,0.14,0.21,1.29,0.016,0.008,0.21,0.02,0.06,0.09,0.03,0.021,0.0065,0.39,0,100,456,572,19,69
CbG,0.14,0.21,1.29,0.016,0.008,0.21,0.02,0.06,0.09,0.03,0.021,0.0065,0.39,0,300,432,602,18,62
CbG,0.14,0.21,1.29,0.016,0.008,0.21,0.02,0.06,0.09,0.03,0.021,0.0065,0.39,0,400,422,548,25,71
CbG,0.14,0.21,1.29,0.016,0.008,0.21,0.02,0.06,0.09,0.03,0.021,0.0065,0.39,0,500,357,433,26,77
CbG,0.14,0.21,1.29,0.016,0.008,0.21,0.02,0.06,0.09,0.03,0.021,0.0065,0.39,0,600,230,310,37,81
CbH,0.148,0.49,1.27,0.03,0.005,0.04,0.19,0.02,0.03,0.07,0.036,0.0065,0.429,0,100,497,593,22,77
CbH,0.148,0.49,1.27,0.03,0.005,0.04,0.19,0.02,0.03,0.07,0.036,0.0065,0.429,0,300,451,618,24,71
CbH,0.148,0.49,1.27,0.03,0.005,0.04,0.19,0.02,0.03,0.07,0.036,0.0065,0.429,0,400,415,544,28,82
CbH,0.148,0.49,1.27,0.03,0.005,0.04,0.19,0.02,0.03,0.07,0.036,0.0065,0.429,0,500,328,409,34,90
CbH,0.148,0.49,1.27,0.03,0.005,0.04,0.19,0.02,0.03,0.07,0.036,0.0065,0.429,0,600,190,282,47,89
CbJ,0.17,0.52,1.27,0.017,0.015,0.02,0.02,0.1,0.02,0.05,0.049,0.0026,0.436,0,100,637,736,18,69
CbJ,0.17,0.52,1.27,0.017,0.015,0.02,0.02,0.1,0.02,0.05,0.049,0.0026,0.436,0,300,573,711,19,69
CbJ,0.17,0.52,1.27,0.017,0.015,0.02,0.02,0.1,0.02,0.05,0.049,0.0026,0.436,0,400,500,630,22,80
CbJ,0.17,0.52,1.27,0.017,0.015,0.02,0.02,0.1,0.02,0.05,0.049,0.0026,0.436,0,500,452,536,17,86
CbJ,0.17,0.52,1.27,0.017,0.015,0.02,0.02,0.1,0.02,0.05,0.049,0.0026,0.436,0,600,247,366,27,85
CbL,0.12,0.33,1.37,0.016,0.012,0.19,0.03,0.01,0.03,0.08,0.042,0.007,0.381,0,100,541,647,21,68
CbL,0.12,0.33,1.37,0.016,0.012,0.19,0.03,0.01,0.03,0.08,0.042,0.007,0.381,0,300,491,660,22,65
CbL,0.12,0.33,1.37,0.016,0.012,0.19,0.03,0.01,0.03,0.08,0.042,0.007,0.381,0,400,450,580,26,77
CbL,0.12,0.33,1.37,0.016,0.012,0.19,0.03,0.01,0.03,0.08,0.042,0.007,0.381,0,500,361,452,27,85
CbL,0.12,0.33,1.37,0.016,0.012,0.19,0.03,0.01,0.03,0.08,0.042,0.007,0.381,0,600,206,311,50,79
CbM,0.13,0.34,1.23,0.012,0.016,0.46,0.03,0.072,0.02,0.042,0.035,0.0065,0.387,0,100,510,612,19,69
CbM,0.13,0.34,1.23,0.012,0.016,0.46,0.03,0.072,0.02,0.042,0.035,0.0065,0.387,0,300,464,636,22,64
CbM,0.13,0.34,1.23,0.012,0.016,0.46,0.03,0.072,0.02,0.042,0.035,0.0065,0.387,0,400,447,566,25,77
CbM,0.13,0.34,1.23,0.012,0.016,0.46,0.03,0.072,0.02,0.042,0.035,0.0065,0.387,0,500,359,436,29,86
CbM,0.13,0.34,1.23,0.012,0.016,0.46,0.03,0.072,0.02,0.042,0.035,0.0065,0.387,0,600,217,312,38,82
CbN,0.12,0.37,1.32,0.012,0.012,0.22,0.03,0.07,0.07,0.04,0.03,0.0064,0.387,0,100,426,533,26,75
CbN,0.12,0.37,1.32,0.012,0.012,0.22,0.03,0.07,0.07,0.04,0.03,0.0064,0.387,0,300,372,571,25,68
CbN,0.12,0.37,1.32,0.012,0.012,0.22,0.03,0.07,0.07,0.04,0.03,0.0064,0.387,0,400,341,509,30,76
CbN,0.12,0.37,1.32,0.012,0.012,0.22,0.03,0.07,0.07,0.04,0.03,0.0064,0.387,0,500,293,389,32,83
CbN,0.12,0.37,1.32,0.012,0.012,0.22,0.03,0.07,0.07,0.04,0.03,0.0064,0.387,0,600,185,258,51,82
CbR,0.16,0.29,1.42,0.013,0.006,0.041,0.054,0.011,0.08,0.079,0.006,0.0048,0.429,0,100,513,642,20,71
CbR,0.16,0.29,1.42,0.013,0.006,0.041,0.054,0.011,0.08,0.079,0.006,0.0048,0.429,0,300,408,614,25,73
CbR,0.16,0.29,1.42,0.013,0.006,0.041,0.054,0.011,0.08,0.079,0.006,0.0048,0.429,0,400,422,551,24,78
CbR,0.16,0.29,1.42,0.013,0.006,0.041,0.054,0.011,0.08,0.079,0.006,0.0048,0.429,0,500,303,408,33,87
CbR,0.16,0.29,1.42,0.013,0.006,0.041,0.054,0.011,0.08,0.079,0.006,0.0048,0.429,0,600,191,290,40,91
CbS,0.123,0.44,1.19,0.021,0.006,0.05,0.2,0.02,0.03,0.07,0.04,0.006,0.39,0,100,486,578,22,77
CbS,0.123,0.44,1.19,0.021,0.006,0.05,0.2,0.02,0.03,0.07,0.04,0.006,0.39,0,300,511,664,23,71
CbS,0.123,0.44,1.19,0.021,0.006,0.05,0.2,0.02,0.03,0.07,0.04,0.006,0.39,0,400,459,576,24,81
CbS,0.123,0.44,1.19,0.021,0.006,0.05,0.2,0.02,0.03,0.07,0.04,0.006,0.39,0,500,338,424,31,90
CbS,0.123,0.44,1.19,0.021,0.006,0.05,0.2,0.02,0.03,0.07,0.04,0.006,0.39,0,600,206,317,51,87
CbT,0.14,0.38,1.24,0.014,0.014,0.43,0.03,0.084,0.05,0.043,0.04,0.0066,0.403,0,100,508,614,20,71
CbT,0.14,0.38,1.24,0.014,0.014,0.43,0.03,0.084,0.05,0.043,0.04,0.0066,0.403,0,300,471,637,21,68
CbT,0.14,0.38,1.24,0.014,0.014,0.43,0.03,0.084,0.05,0.043,0.04,0.0066,0.403,0,400,438,559,26,78
CbT,0.14,0.38,1.24,0.014,0.014,0.43,0.03,0.084,0.05,0.043,0.04,0.0066,0.403,0,500,362,441,24,85
CbT,0.14,0.38,1.24,0.014,0.014,0.43,0.03,0.084,0.05,0.043,0.04,0.0066,0.403,0,600,229,313,39,83
CbU,0.14,0.33,1.45,0.025,0.012,0.18,0.03,0.01,0.02,0.06,0.05,0.0051,0.412,0,100,521,625,20,69
CbU,0.14,0.33,1.45,0.025,0.012,0.18,0.03,0.01,0.02,0.06,0.05,0.0051,0.412,0,300,488,655,21,64
CbU,0.14,0.33,1.45,0.025,0.012,0.18,0.03,0.01,0.02,0.06,0.05,0.0051,0.412,0,400,437,570,26,76
CbU,0.14,0.33,1.45,0.025,0.012,0.18,0.03,0.01,0.02,0.06,0.05,0.0051,0.412,0,500,345,444,36,88
CbU,0.14,0.33,1.45,0.025,0.012,0.18,0.03,0.01,0.02,0.06,0.05,0.0051,0.412,0,600,193,299,54,88
CbV,0.15,0.25,1.38,0.014,0.006,0.04,0.041,0.006,0.08,0.088,0.015,0.0076,0.407,0,100,468,586,24,71
CbV,0.15,0.25,1.38,0.014,0.006,0.04,0.041,0.006,0.08,0.088,0.015,0.0076,0.407,0,300,399,583,20,67
CbV,0.15,0.25,1.38,0.014,0.006,0.04,0.041,0.006,0.08,0.088,0.015,0.0076,0.407,0,400,360,517,24,72
CbV,0.15,0.25,1.38,0.014,0.006,0.04,0.041,0.006,0.08,0.088,0.015,0.0076,0.407,0,500,265,378,39,79
CbV,0.15,0.25,1.38,0.014,0.006,0.04,0.041,0.006,0.08,0.088,0.015,0.0076,0.407,0,600,185,270,31,77
CbW,0.143,0.5,1.2,0.03,0.007,0.06,0.17,0.02,0.02,0.07,0.029,0.0068,0.409,0,100,463,569,24,78
CbW,0.143,0.5,1.2,0.03,0.007,0.06,0.17,0.02,0.02,0.07,0.029,0.0068,0.409,0,300,425,604,25,74
CbW,0.143,0.5,1.2,0.03,0.007,0.06,0.17,0.02,0.02,0.07,0.029,0.0068,0.409,0,400,407,530,30,82
CbW,0.143,0.5,1.2,0.03,0.007,0.06,0.17,0.02,0.02,0.07,0.029,0.0068,0.409,0,500,328,416,38,89
CbW,0.143,0.5,1.2,0.03,0.007,0.06,0.17,0.02,0.02,0.07,0.029,0.0068,0.409,0,600,193,279,54,91
CbX,0.17,0.49,1.26,0.013,0.01,0.01,0.02,0.09,0.02,0.04,0.045,0.0025,0.429,0,100,508,640,19,69
CbX,0.17,0.49,1.26,0.013,0.01,0.01,0.02,0.09,0.02,0.04,0.045,0.0025,0.429,0,300,461,634,21,70
CbX,0.17,0.49,1.26,0.013,0.01,0.01,0.02,0.09,0.02,0.04,0.045,0.0025,0.429,0,400,413,566,28,83
CbX,0.17,0.49,1.26,0.013,0.01,0.01,0.02,0.09,0.02,0.04,0.045,0.0025,0.429,0,500,394,478,25,88
CbX,0.17,0.49,1.26,0.013,0.01,0.01,0.02,0.09,0.02,0.04,0.045,0.0025,0.429,0,600,234,330,37,84
CbY,0.13,0.42,1.28,0.014,0.012,0.21,0.22,0.05,0.04,0.03,0.037,0.0072,0.424,0,100,451,567,24,76
CbY,0.13,0.42,1.28,0.014,0.012,0.21,0.22,0.05,0.04,0.03,0.037,0.0072,0.424,0,300,410,607,27,70
CbY,0.13,0.42,1.28,0.014,0.012,0.21,0.22,0.05,0.04,0.03,0.037,0.0072,0.424,0,400,378,532,29,79
CbY,0.13,0.42,1.28,0.014,0.012,0.21,0.22,0.05,0.04,0.03,0.037,0.0072,0.424,0,500,325,405,32,85
CbY,0.13,0.42,1.28,0.014,0.012,0.21,0.22,0.05,0.04,0.03,0.037,0.0072,0.424,0,600,193,276,50,78
CbZ,0.16,0.41,1.48,0.014,0.01,0.02,0.02,0.01,0.03,0.08,0.033,0.0079,0.436,0,100,546,663,17,60
CbZ,0.16,0.41,1.48,0.014,0.01,0.02,0.02,0.01,0.03,0.08,0.033,0.0079,0.436,0,300,483,664,18,59
CbZ,0.16,0.41,1.48,0.014,0.01,0.02,0.02,0.01,0.03,0.08,0.033,0.0079,0.436,0,400,452,583,24,71
CbZ,0.16,0.41,1.48,0.014,0.01,0.02,0.02,0.01,0.03,0.08,0.033,0.0079,0.436,0,500,360,450,31,83
CbZ,0.16,0.41,1.48,0.014,0.01,0.02,0.02,0.01,0.03,0.08,0.033,0.0079,0.436,0,600,198,313,30,77
CCA,0.23,0.23,1.23,0.027,0.012,0.03,0.04,0.017,0.01,0.009,0.003,0.0111,0,0.0017,100,371,558,20,65
CCA,0.23,0.23,1.23,0.027,0.012,0.03,0.04,0.017,0.01,0.009,0.003,0.0111,0,0.0017,200,358,690,17,45
CCA,0.23,0.23,1.23,0.027,0.012,0.03,0.04,0.017,0.01,0.009,0.003,0.0111,0,0.0017,300,290,677,27,59
CCA,0.23,0.23,1.23,0.027,0.012,0.03,0.04,0.017,0.01,0.009,0.003,0.0111,0,0.0017,400,243,572,29,67
CCA,0.23,0.23,1.23,0.027,0.012,0.03,0.04,0.017,0.01,0.009,0.003,0.0111,0,0.0017,500,181,416,33,79
CCB,0.22,0.22,1.24,0.021,0.008,0.03,0.05,0.017,0.01,0.005,0.005,0.0116,0,0.0017,27,382,580,28,70
CCB,0.22,0.22,1.24,0.021,0.008,0.03,0.05,0.017,0.01,0.005,0.005,0.0116,0,0.0017,150,372,650,18,49
CCB,0.22,0.22,1.24,0.021,0.008,0.03,0.05,0.017,0.01,0.005,0.005,0.0116,0,0.0017,250,326,710,22,48
CCB,0.22,0.22,1.24,0.021,0.008,0.03,0.05,0.017,0.01,0.005,0.005,0.0116,0,0.0017,350,268,632,28,65
CCB,0.22,0.22,1.24,0.021,0.008,0.03,0.05,0.017,0.01,0.005,0.005,0.0116,0,0.0017,450,224,500,29,72
CCB,0.22,0.22,1.24,0.021,0.008,0.03,0.05,0.017,0.01,0.005,0.005,0.0116,0,0.0017,550,200,328,40,86